<?xml version="1.0" ?>
<!-- =================================================================================== -->
<!-- |    This document was autogenerated by xacro from /home/ahagi/master_ros2/src/bebopv2_description/urdf/bebopv2.xacro | -->
<!-- |    EDITING THIS FILE BY HAND IS NOT RECOMMENDED                                 | -->
<!-- =================================================================================== -->
<robot name="bebopv2">
  <material name="silver">
    <color rgba="0.700 0.700 0.700 1.000"/>
  </material>
  <gazebo reference="base_link">
    <material>Gazebo/Silver</material>
    <mu1>0.2</mu1>
    <mu2>0.2</mu2>
    <self_collide>true</self_collide>
    <gravity>true</gravity>
  </gazebo>
  <gazebo reference="femur_left_1">
    <material>Gazebo/Silver</material>
    <mu1>0.2</mu1>
    <mu2>0.2</mu2>
    <self_collide>true</self_collide>
  </gazebo>
  <gazebo reference="femur_right_1">
    <material>Gazebo/Silver</material>
    <mu1>0.2</mu1>
    <mu2>0.2</mu2>
    <self_collide>true</self_collide>
  </gazebo>
  <gazebo reference="shin_left_1">
    <material>Gazebo/Silver</material>
    <mu1>0.2</mu1>
    <mu2>0.2</mu2>
    <self_collide>true</self_collide>
  </gazebo>
  <gazebo reference="shin_right_1">
    <material>Gazebo/Silver</material>
    <mu1>0.2</mu1>
    <mu2>0.2</mu2>
    <self_collide>true</self_collide>
  </gazebo>
  <gazebo reference="foot_left_1">
    <material>Gazebo/Silver</material>
    <mu1>0.2</mu1>
    <mu2>0.2</mu2>
    <self_collide>true</self_collide>
  </gazebo>
  <gazebo reference="foot_right_1">
    <material>Gazebo/Silver</material>
    <mu1>0.2</mu1>
    <mu2>0.2</mu2>
    <self_collide>true</self_collide>
  </gazebo>
  <gazebo reference="hip_abduction_right_1">
    <material>Gazebo/Silver</material>
    <mu1>0.2</mu1>
    <mu2>0.2</mu2>
    <self_collide>true</self_collide>
  </gazebo>
  <gazebo reference="hip_abduction_left_1">
    <material>Gazebo/Silver</material>
    <mu1>0.2</mu1>
    <mu2>0.2</mu2>
    <self_collide>true</self_collide>
  </gazebo>
  <link name="base_link">
    <inertial>
      <origin rpy="0 0 0" xyz="-8.495725208879161e-05 0.002060204806872657 0.06042048201634313"/>
      <mass value="10.498536136255769"/>
      <inertia ixx="0.135473" ixy="0.000202" ixz="-0.002579" iyy="0.076749" iyz="-0.001328" izz="0.084177"/>
    </inertial>
    <visual>
      <origin rpy="0 0 0" xyz="0 0 0"/>
      <geometry>
        <mesh filename="file:///workspace/bebop_bot/ros2/src/bebopv2_description/meshes/base_link.stl" scale="0.001 0.001 0.001"/>
      </geometry>
      <material name="silver"/>
    </visual>
    <collision>
      <origin rpy="0 0 0" xyz="0 0 0"/>
      <geometry>
        <mesh filename="file:///workspace/bebop_bot/ros2/src/bebopv2_description/meshes/base_link.stl" scale="0.001 0.001 0.001"/>
      </geometry>
    </collision>
  </link>
  <link name="femur_left_1">
    <inertial>
      <origin rpy="0 0 0" xyz="0.03177093685295705 0.0003179774752826714 -0.18130160282671148"/>
      <mass value="1.741996667034525"/>
      <inertia ixx="0.023689" ixy="-2e-06" ixz="0.00145" iyy="0.024237" iyz="0.000107" izz="0.001703"/>
    </inertial>
    <visual>
      <origin rpy="0 0 0" xyz="-0.025761 -0.2205 -0.013132"/>
      <geometry>
        <mesh filename="file:///workspace/bebop_bot/ros2/src/bebopv2_description/meshes/femur_left_1.stl" scale="0.001 0.001 0.001"/>
      </geometry>
      <material name="silver"/>
    </visual>
    <collision>
      <origin rpy="0 0 0" xyz="-0.025761 -0.2205 -0.013132"/>
      <geometry>
        <mesh filename="file:///workspace/bebop_bot/ros2/src/bebopv2_description/meshes/femur_left_1.stl" scale="0.001 0.001 0.001"/>
      </geometry>
    </collision>
  </link>
  <link name="femur_right_1">
    <inertial>
      <origin rpy="0 0 0" xyz="0.03210238385367442 -0.00031797682024858887 -0.18130148887841402"/>
      <mass value="1.741992832749943"/>
      <inertia ixx="0.023688" ixy="4e-06" ixz="0.001494" iyy="0.024244" iyz="-0.000107" izz="0.001709"/>
    </inertial>
    <visual>
      <origin rpy="0 0 0" xyz="-0.026023 0.2195 -0.013"/>
      <geometry>
        <mesh filename="file:///workspace/bebop_bot/ros2/src/bebopv2_description/meshes/femur_right_1.stl" scale="0.001 0.001 0.001"/>
      </geometry>
      <material name="silver"/>
    </visual>
    <collision>
      <origin rpy="0 0 0" xyz="-0.026023 0.2195 -0.013"/>
      <geometry>
        <mesh filename="file:///workspace/bebop_bot/ros2/src/bebopv2_description/meshes/femur_right_1.stl" scale="0.001 0.001 0.001"/>
      </geometry>
    </collision>
  </link>
  <link name="shin_left_1">
    <inertial>
      <origin rpy="0 0 0" xyz="3.846626426318167e-05 0.01659813777561367 -0.12318432363895004"/>
      <mass value="0.11370113593752607"/>
      <inertia ixx="0.000949" ixy="-0.0" ixz="-0.0" iyy="0.000959" iyz="-6e-06" izz="2.1e-05"/>
    </inertial>
    <visual>
      <origin rpy="0 0 0" xyz="-0.063261 -0.2482 0.280902"/>
      <geometry>
        <mesh filename="file:///workspace/bebop_bot/ros2/src/bebopv2_description/meshes/shin_left_1.stl" scale="0.001 0.001 0.001"/>
      </geometry>
      <material name="silver"/>
    </visual>
    <collision>
      <origin rpy="0 0 0" xyz="-0.063261 -0.2482 0.280902"/>
      <geometry>
        <mesh filename="file:///workspace/bebop_bot/ros2/src/bebopv2_description/meshes/shin_left_1.stl" scale="0.001 0.001 0.001"/>
      </geometry>
    </collision>
  </link>
  <link name="shin_right_1">
    <inertial>
      <origin rpy="0 0 0" xyz="-0.0021891088643529594 -0.016598079567325258 -0.12316565094474391"/>
      <mass value="0.11369998148988655"/>
      <inertia ixx="0.000949" ixy="0.0" ixz="-1.6e-05" iyy="0.000959" iyz="6e-06" izz="2.2e-05"/>
    </inertial>
    <visual>
      <origin rpy="0 0 0" xyz="-0.063523 0.2472 0.281034"/>
      <geometry>
        <mesh filename="file:///workspace/bebop_bot/ros2/src/bebopv2_description/meshes/shin_right_1.stl" scale="0.001 0.001 0.001"/>
      </geometry>
      <material name="silver"/>
    </visual>
    <collision>
      <origin rpy="0 0 0" xyz="-0.063523 0.2472 0.281034"/>
      <geometry>
        <mesh filename="file:///workspace/bebop_bot/ros2/src/bebopv2_description/meshes/shin_right_1.stl" scale="0.001 0.001 0.001"/>
      </geometry>
    </collision>
  </link>
  <link name="foot_left_1">
    <inertial>
      <origin rpy="0 0 0" xyz="0.022192420913894034 -0.01606998038885915 -0.0408213906831868"/>
      <mass value="0.6420025158679283"/>
      <inertia ixx="0.000925" ixy="-6.5e-05" ixz="0.000184" iyy="0.002283" iyz="0.000124" izz="0.002103"/>
    </inertial>
    <visual>
      <origin rpy="0 0 0" xyz="-0.063265 -0.2482 0.534402"/>
      <geometry>
        <mesh filename="file:///workspace/bebop_bot/ros2/src/bebopv2_description/meshes/foot_left_1.stl" scale="0.001 0.001 0.001"/>
      </geometry>
      <material name="silver"/>
    </visual>
    <collision>
      <origin rpy="0 0 0" xyz="-0.063265 -0.2482 0.534402"/>
      <geometry>
        <mesh filename="file:///workspace/bebop_bot/ros2/src/bebopv2_description/meshes/foot_left_1.stl" scale="0.001 0.001 0.001"/>
      </geometry>
    </collision>
  </link>
  <link name="foot_right_1">
    <inertial>
      <origin rpy="0 0 0" xyz="0.02218934865992219 0.016069987053803497 -0.04081687775985443"/>
      <mass value="0.6420010099946694"/>
      <inertia ixx="0.000925" ixy="6.5e-05" ixz="0.000184" iyy="0.002283" iyz="-0.000124" izz="0.002103"/>
    </inertial>
    <visual>
      <origin rpy="0 0 0" xyz="-0.059094 0.2472 0.534495"/>
      <geometry>
        <mesh filename="file:///workspace/bebop_bot/ros2/src/bebopv2_description/meshes/foot_right_1.stl" scale="0.001 0.001 0.001"/>
      </geometry>
      <material name="silver"/>
    </visual>
    <collision>
      <origin rpy="0 0 0" xyz="-0.059094 0.2472 0.534495"/>
      <geometry>
        <mesh filename="file:///workspace/bebop_bot/ros2/src/bebopv2_description/meshes/foot_right_1.stl" scale="0.001 0.001 0.001"/>
      </geometry>
    </collision>
  </link>
  <link name="hip_abduction_right_1">
    <inertial>
      <origin rpy="0 0 0" xyz="-0.0003222024240098673 -0.06711052938146264 -1.0231419950193846e-05"/>
      <mass value="1.000019792580193"/>
      <inertia ixx="0.002281" ixy="-1e-06" ixz="-2e-06" iyy="0.001675" iyz="0.0" izz="0.001808"/>
    </inertial>
    <visual>
      <origin rpy="0 0 0" xyz="0.003527 0.1495 -0.013"/>
      <geometry>
        <mesh filename="file:///workspace/bebop_bot/ros2/src/bebopv2_description/meshes/hip_abduction_right_1.stl" scale="0.001 0.001 0.001"/>
      </geometry>
      <material name="silver"/>
    </visual>
    <collision>
      <origin rpy="0 0 0" xyz="0.003527 0.1495 -0.013"/>
      <geometry>
        <mesh filename="file:///workspace/bebop_bot/ros2/src/bebopv2_description/meshes/hip_abduction_right_1.stl" scale="0.001 0.001 0.001"/>
      </geometry>
    </collision>
  </link>
  <link name="hip_abduction_left_1">
    <inertial>
      <origin rpy="0 0 0" xyz="-0.0003221682749529886 0.0671105256944631 1.0147989652034214e-05"/>
      <mass value="1.0000098137346085"/>
      <inertia ixx="0.002281" ixy="1e-06" ixz="2e-06" iyy="0.001675" iyz="0.0" izz="0.001808"/>
    </inertial>
    <visual>
      <origin rpy="0 0 0" xyz="0.003789 -0.1505 -0.013132"/>
      <geometry>
        <mesh filename="file:///workspace/bebop_bot/ros2/src/bebopv2_description/meshes/hip_abduction_left_1.stl" scale="0.001 0.001 0.001"/>
      </geometry>
      <material name="silver"/>
    </visual>
    <collision>
      <origin rpy="0 0 0" xyz="0.003789 -0.1505 -0.013132"/>
      <geometry>
        <mesh filename="file:///workspace/bebop_bot/ros2/src/bebopv2_description/meshes/hip_abduction_left_1.stl" scale="0.001 0.001 0.001"/>
      </geometry>
    </collision>
  </link>
  <joint name="femur_left_joint" type="revolute">
    <origin rpy="0 0 0" xyz="0.02955 0.07 0.0"/>
    <parent link="hip_abduction_left_1"/>
    <child link="femur_left_1"/>
    <axis xyz="1.0 -0.0 0.0"/>
    <limit effort="100" lower="-0.349066" upper="0.785398" velocity="100"/>
  </joint>
  <joint name="femur_right_joint" type="revolute">
    <origin rpy="0 0 0" xyz="0.02955 -0.07 0.0"/>
    <parent link="hip_abduction_right_1"/>
    <child link="femur_right_1"/>
    <axis xyz="1.0 -0.0 -0.0"/>
    <limit effort="100" lower="-0.785398" upper="0.349066" velocity="100"/>
  </joint>
  <joint name="shin_left_joint" type="revolute">
    <origin rpy="0 0 0" xyz="0.0375 0.0277 -0.294034"/>
    <parent link="femur_left_1"/>
    <child link="shin_left_1"/>
    <axis xyz="0.0 1.0 0.0"/>
    <limit effort="100" lower="-0.785398" upper="1.570796" velocity="100"/>
  </joint>
  <joint name="shin_right_joint" type="revolute">
    <origin rpy="0 0 0" xyz="0.0375 -0.0277 -0.294034"/>
    <parent link="femur_right_1"/>
    <child link="shin_right_1"/>
    <axis xyz="-0.0 -1.0 -0.0"/>
    <limit effort="100" lower="-1.570796" upper="0.785398" velocity="100"/>
  </joint>
  <joint name="foot_left_joint" type="revolute">
    <origin rpy="0 0 0" xyz="4e-06 0.0 -0.2535"/>
    <parent link="shin_left_1"/>
    <child link="foot_left_1"/>
    <axis xyz="-0.0 1.0 0.0"/>
    <limit effort="100" lower="-0.523599" upper="0.523599" velocity="100"/>
  </joint>
  <joint name="foot_right_joint" type="revolute">
    <origin rpy="0 0 0" xyz="-0.004429 0.0 -0.253461"/>
    <parent link="shin_right_1"/>
    <child link="foot_right_1"/>
    <axis xyz="-0.0 -1.0 -0.0"/>
    <limit effort="100" lower="-0.523599" upper="0.523599" velocity="100"/>
  </joint>
  <joint name="hip_abduction_right_joint" type="revolute">
    <origin rpy="0 0 0" xyz="-0.003527 -0.1495 0.013"/>
    <parent link="base_link"/>
    <child link="hip_abduction_right_1"/>
    <axis xyz="-0.0 -1.0 -0.0"/>
    <limit effort="100" lower="-0.785398" upper="0.785398" velocity="100"/>
  </joint>
  <joint name="hip_abduction_left_joint" type="revolute">
    <origin rpy="0 0 0" xyz="-0.003789 0.1505 0.013132"/>
    <parent link="base_link"/>
    <child link="hip_abduction_left_1"/>
    <axis xyz="0.0 1.0 -0.0"/>
    <limit effort="100" lower="-0.785398" upper="0.785398" velocity="100"/>
  </joint>
</robot>
