<?xml version="1.0" ?>
<!-- =================================================================================== -->
<!-- |    This document was autogenerated by xacro from /home/ahagi/master_ros2_ws/src/bebopv2_description/urdf/bebopv2.xacro | -->
<!-- |    EDITING THIS FILE BY HAND IS NOT RECOMMENDED                                 | -->
<!-- =================================================================================== -->
<robot name="bebopv2">
  <material name="silver">
    <color rgba="0.700 0.700 0.700 1.000"/>
  </material>
  <gazebo reference="base_link">
    <material>Gazebo/Silver</material>
    <mu1>0.2</mu1>
    <mu2>0.2</mu2>
    <self_collide>true</self_collide>
    <gravity>true</gravity>
  </gazebo>
  <gazebo reference="hip_abduction_left_1_1">
    <material>Gazebo/Silver</material>
    <mu1>0.2</mu1>
    <mu2>0.2</mu2>
    <self_collide>true</self_collide>
  </gazebo>
  <gazebo reference="hip_abduction_right_1_1">
    <material>Gazebo/Silver</material>
    <mu1>0.2</mu1>
    <mu2>0.2</mu2>
    <self_collide>true</self_collide>
  </gazebo>
  <gazebo reference="femur_left_1_1">
    <material>Gazebo/Silver</material>
    <mu1>0.2</mu1>
    <mu2>0.2</mu2>
    <self_collide>true</self_collide>
  </gazebo>
  <gazebo reference="femur_right_1_1">
    <material>Gazebo/Silver</material>
    <mu1>0.2</mu1>
    <mu2>0.2</mu2>
    <self_collide>true</self_collide>
  </gazebo>
  <gazebo reference="shin_left_1_1">
    <material>Gazebo/Silver</material>
    <mu1>0.2</mu1>
    <mu2>0.2</mu2>
    <self_collide>true</self_collide>
  </gazebo>
  <gazebo reference="shin_right_1_1">
    <material>Gazebo/Silver</material>
    <mu1>0.2</mu1>
    <mu2>0.2</mu2>
    <self_collide>true</self_collide>
  </gazebo>
  <gazebo reference="foot_left_1_1">
    <material>Gazebo/Silver</material>
    <mu1>0.2</mu1>
    <mu2>0.2</mu2>
    <self_collide>true</self_collide>
  </gazebo>
  <gazebo reference="foot_right_1_1">
    <material>Gazebo/Silver</material>
    <mu1>0.2</mu1>
    <mu2>0.2</mu2>
    <self_collide>true</self_collide>
  </gazebo>
  <link name="base_link">
    <inertial>
      <origin rpy="0 0 0" xyz="0.007385904694151062 -0.0004782319133016371 0.03368322966647506"/>
      <mass value="2.683107573914711"/>
      <inertia ixx="0.035466" ixy="4.2e-05" ixz="-0.001118" iyy="0.017273" iyz="-1.7e-05" izz="0.025862"/>
    </inertial>
    <visual>
      <origin rpy="0 0 0" xyz="0 0 0"/>
      <geometry>
        <mesh filename="file:///workspace/bebop_bot/ros2_ws/src/bebopv2_description/meshes/base_link.stl" scale="0.001 0.001 0.001"/>
      </geometry>
      <material name="silver"/>
    </visual>
    <collision>
      <origin rpy="0 0 0" xyz="0 0 0"/>
      <geometry>
        <mesh filename="file:///workspace/bebop_bot/ros2_ws/src/bebopv2_description/meshes/base_link.stl" scale="0.001 0.001 0.001"/>
      </geometry>
    </collision>
  </link>
  <link name="hip_abduction_left_1_1">
    <inertial>
      <origin rpy="0 0 0" xyz="-0.0003217598941065208 0.06711052569446321 1.0147989649067783e-05"/>
      <mass value="0.38495857785704823"/>
      <inertia ixx="0.000878" ixy="0.0" ixz="1e-06" iyy="0.000645" iyz="0.0" izz="0.000696"/>
    </inertial>
    <visual>
      <origin rpy="0 0 0" xyz="0.000262 -0.15 -0.000132"/>
      <geometry>
        <mesh filename="file:///workspace/bebop_bot/ros2_ws/src/bebopv2_description/meshes/hip_abduction_left_1_1.stl" scale="0.001 0.001 0.001"/>
      </geometry>
      <material name="silver"/>
    </visual>
    <collision>
      <origin rpy="0 0 0" xyz="0.000262 -0.15 -0.000132"/>
      <geometry>
        <mesh filename="file:///workspace/bebop_bot/ros2_ws/src/bebopv2_description/meshes/hip_abduction_left_1_1.stl" scale="0.001 0.001 0.001"/>
      </geometry>
    </collision>
  </link>
  <link name="hip_abduction_right_1_1">
    <inertial>
      <origin rpy="0 0 0" xyz="-0.0003217940431635766 -0.06711052938146245 -1.023141995292347e-05"/>
      <mass value="0.3849585610474383"/>
      <inertia ixx="0.000878" ixy="-0.0" ixz="-1e-06" iyy="0.000645" iyz="0.0" izz="0.000696"/>
    </inertial>
    <visual>
      <origin rpy="0 0 0" xyz="0.0 0.151 -0.0"/>
      <geometry>
        <mesh filename="file:///workspace/bebop_bot/ros2_ws/src/bebopv2_description/meshes/hip_abduction_right_1_1.stl" scale="0.001 0.001 0.001"/>
      </geometry>
      <material name="silver"/>
    </visual>
    <collision>
      <origin rpy="0 0 0" xyz="0.0 0.151 -0.0"/>
      <geometry>
        <mesh filename="file:///workspace/bebop_bot/ros2_ws/src/bebopv2_description/meshes/hip_abduction_right_1_1.stl" scale="0.001 0.001 0.001"/>
      </geometry>
    </collision>
  </link>
  <link name="femur_left_1_1">
    <inertial>
      <origin rpy="0 0 0" xyz="0.03177134523380352 0.00031797747528269915 -0.18130160282671445"/>
      <mass value="6.100588872036469"/>
      <inertia ixx="0.082959" ixy="-8e-06" ixz="0.005077" iyy="0.08488" iyz="0.000373" izz="0.005962"/>
    </inertial>
    <visual>
      <origin rpy="0 0 0" xyz="-0.029288 -0.22 -0.000132"/>
      <geometry>
        <mesh filename="file:///workspace/bebop_bot/ros2_ws/src/bebopv2_description/meshes/femur_left_1_1.stl" scale="0.001 0.001 0.001"/>
      </geometry>
      <material name="silver"/>
    </visual>
    <collision>
      <origin rpy="0 0 0" xyz="-0.029288 -0.22 -0.000132"/>
      <geometry>
        <mesh filename="file:///workspace/bebop_bot/ros2_ws/src/bebopv2_description/meshes/femur_left_1_1.stl" scale="0.001 0.001 0.001"/>
      </geometry>
    </collision>
  </link>
  <link name="femur_right_1_1">
    <inertial>
      <origin rpy="0 0 0" xyz="0.0321027922345207 -0.00031797682024858887 -0.18130148887841674"/>
      <mass value="6.100585251669615"/>
      <inertia ixx="0.082959" ixy="1.4e-05" ixz="0.005232" iyy="0.084903" iyz="-0.000373" izz="0.005985"/>
    </inertial>
    <visual>
      <origin rpy="0 0 0" xyz="-0.02955 0.221 0.0"/>
      <geometry>
        <mesh filename="file:///workspace/bebop_bot/ros2_ws/src/bebopv2_description/meshes/femur_right_1_1.stl" scale="0.001 0.001 0.001"/>
      </geometry>
      <material name="silver"/>
    </visual>
    <collision>
      <origin rpy="0 0 0" xyz="-0.02955 0.221 0.0"/>
      <geometry>
        <mesh filename="file:///workspace/bebop_bot/ros2_ws/src/bebopv2_description/meshes/femur_right_1_1.stl" scale="0.001 0.001 0.001"/>
      </geometry>
    </collision>
  </link>
  <link name="shin_left_1_1">
    <inertial>
      <origin rpy="0 0 0" xyz="3.887590066825597e-05 0.016598133015893995 -0.12318420193029112"/>
      <mass value="0.23016891060875985"/>
      <inertia ixx="0.001921" ixy="-0.0" ixz="-0.0" iyy="0.001941" iyz="-1.2e-05" izz="4.3e-05"/>
    </inertial>
    <visual>
      <origin rpy="0 0 0" xyz="-0.066788 -0.2477 0.293902"/>
      <geometry>
        <mesh filename="file:///workspace/bebop_bot/ros2_ws/src/bebopv2_description/meshes/shin_left_1_1.stl" scale="0.001 0.001 0.001"/>
      </geometry>
      <material name="silver"/>
    </visual>
    <collision>
      <origin rpy="0 0 0" xyz="-0.066788 -0.2477 0.293902"/>
      <geometry>
        <mesh filename="file:///workspace/bebop_bot/ros2_ws/src/bebopv2_description/meshes/shin_left_1_1.stl" scale="0.001 0.001 0.001"/>
      </geometry>
    </collision>
  </link>
  <link name="shin_right_1_1">
    <inertial>
      <origin rpy="0 0 0" xyz="-0.0021886908544472145 -0.016598132485373535 -0.12316472976088472"/>
      <mass value="0.23016883140801822"/>
      <inertia ixx="0.001921" ixy="0.0" ixz="-3.2e-05" iyy="0.001941" iyz="1.2e-05" izz="4.4e-05"/>
    </inertial>
    <visual>
      <origin rpy="0 0 0" xyz="-0.06705 0.2487 0.294034"/>
      <geometry>
        <mesh filename="file:///workspace/bebop_bot/ros2_ws/src/bebopv2_description/meshes/shin_right_1_1.stl" scale="0.001 0.001 0.001"/>
      </geometry>
      <material name="silver"/>
    </visual>
    <collision>
      <origin rpy="0 0 0" xyz="-0.06705 0.2487 0.294034"/>
      <geometry>
        <mesh filename="file:///workspace/bebop_bot/ros2_ws/src/bebopv2_description/meshes/shin_right_1_1.stl" scale="0.001 0.001 0.001"/>
      </geometry>
    </collision>
  </link>
  <link name="foot_left_1_1">
    <inertial>
      <origin rpy="0 0 0" xyz="0.02219188787582449 -0.016069983036660074 -0.040821402975144694"/>
      <mass value="0.938066903777968"/>
      <inertia ixx="0.001351" ixy="-9.6e-05" ixz="0.000268" iyy="0.003336" iyz="0.00018" izz="0.003073"/>
    </inertial>
    <visual>
      <origin rpy="0 0 0" xyz="-0.066793 -0.2477 0.547402"/>
      <geometry>
        <mesh filename="file:///workspace/bebop_bot/ros2_ws/src/bebopv2_description/meshes/foot_left_1_1.stl" scale="0.001 0.001 0.001"/>
      </geometry>
      <material name="silver"/>
    </visual>
    <collision>
      <origin rpy="0 0 0" xyz="-0.066793 -0.2477 0.547402"/>
      <geometry>
        <mesh filename="file:///workspace/bebop_bot/ros2_ws/src/bebopv2_description/meshes/foot_left_1_1.stl" scale="0.001 0.001 0.001"/>
      </geometry>
    </collision>
  </link>
  <link name="foot_right_1_1">
    <inertial>
      <origin rpy="0 0 0" xyz="0.02218978231016064 0.016069982543298805 -0.040816882308905234"/>
      <mass value="0.9380669235063296"/>
      <inertia ixx="0.001352" ixy="9.6e-05" ixz="0.000268" iyy="0.003336" iyz="-0.000181" izz="0.003073"/>
    </inertial>
    <visual>
      <origin rpy="0 0 0" xyz="-0.062621 0.2487 0.547495"/>
      <geometry>
        <mesh filename="file:///workspace/bebop_bot/ros2_ws/src/bebopv2_description/meshes/foot_right_1_1.stl" scale="0.001 0.001 0.001"/>
      </geometry>
      <material name="silver"/>
    </visual>
    <collision>
      <origin rpy="0 0 0" xyz="-0.062621 0.2487 0.547495"/>
      <geometry>
        <mesh filename="file:///workspace/bebop_bot/ros2_ws/src/bebopv2_description/meshes/foot_right_1_1.stl" scale="0.001 0.001 0.001"/>
      </geometry>
    </collision>
  </link>
  <joint name="hip_abduction_left_joint" type="revolute">
    <origin rpy="0 0 0" xyz="-0.000262 0.15 0.000132"/>
    <parent link="base_link"/>
    <child link="hip_abduction_left_1_1"/>
    <axis xyz="0.0 1.0 -0.0"/>
    <limit effort="100" lower="-0.785398" upper="0.785398" velocity="100"/>
  </joint>
  <joint name="hip_abduction_right_joint" type="revolute">
    <origin rpy="0 0 0" xyz="0.0 -0.151 0.0"/>
    <parent link="base_link"/>
    <child link="hip_abduction_right_1_1"/>
    <axis xyz="-0.0 -1.0 0.0"/>
    <limit effort="100" lower="-0.785398" upper="0.785398" velocity="100"/>
  </joint>
  <joint name="femur_left_joint" type="revolute">
    <origin rpy="0 0 0" xyz="0.02955 0.07 0.0"/>
    <parent link="hip_abduction_left_1_1"/>
    <child link="femur_left_1_1"/>
    <axis xyz="1.0 -0.0 0.0"/>
    <limit effort="100" lower="-0.349066" upper="0.785398" velocity="100"/>
  </joint>
  <joint name="femur_right_joint" type="revolute">
    <origin rpy="0 0 0" xyz="0.02955 -0.07 -0.0"/>
    <parent link="hip_abduction_right_1_1"/>
    <child link="femur_right_1_1"/>
    <axis xyz="1.0 -0.0 -0.0"/>
    <limit effort="100" lower="-0.785398" upper="0.349066" velocity="100"/>
  </joint>
  <joint name="shin_left_joint" type="revolute">
    <origin rpy="0 0 0" xyz="0.0375 0.0277 -0.294034"/>
    <parent link="femur_left_1_1"/>
    <child link="shin_left_1_1"/>
    <axis xyz="0.0 1.0 0.0"/>
    <limit effort="100" lower="-0.785398" upper="1.570796" velocity="100"/>
  </joint>
  <joint name="shin_right_joint" type="revolute">
    <origin rpy="0 0 0" xyz="0.0375 -0.0277 -0.294034"/>
    <parent link="femur_right_1_1"/>
    <child link="shin_right_1_1"/>
    <axis xyz="-0.0 -1.0 -0.0"/>
    <limit effort="100" lower="-1.570796" upper="0.785398" velocity="100"/>
  </joint>
  <joint name="foot_left_joint" type="revolute">
    <origin rpy="0 0 0" xyz="5e-06 0.0 -0.2535"/>
    <parent link="shin_left_1_1"/>
    <child link="foot_left_1_1"/>
    <axis xyz="-0.0 1.0 0.0"/>
    <limit effort="100" lower="-0.523599" upper="0.523599" velocity="100"/>
  </joint>
  <joint name="foot_right_joint" type="revolute">
    <origin rpy="0 0 0" xyz="-0.004429 0.0 -0.253461"/>
    <parent link="shin_right_1_1"/>
    <child link="foot_right_1_1"/>
    <axis xyz="-0.0 -1.0 -0.0"/>
    <limit effort="100" lower="-0.523599" upper="0.523599" velocity="100"/>
  </joint>
</robot>
